Workbook

Sheet Sheet1
A1: SSO_ID | B1: Year | C1: Complete Address | D1: Address | E1: City | F1: State | G1: Zipcode | H1: Flow_Location | I1: Flow Location(Corrected) | J1: Gallons | K1: Structure_Type | L1: Structure_Type(Corrected) | M1: Excursion_Cause | N1: Excursion_Cause(Corrected) | O1: Start_Date | P1: Start_Time | Q1: End_Date | R1: End_Time | S1: Average_Flow__GPM_ | T1: Corrective_Action | U1: Start_Date_Converted | V1: End_Date_Converted | W1: lat | X1: long
A2: 10424 | B2: 2021 | C2: =CONCATENATE(D2,",",E2,",",F2) -> 8515 HAMMERLY BLVD,Houston,Texas | D2: 8515 HAMMERLY BLVD | E2: Houston | F2: Texas | G2: 77055 | H2: Storm Sewer (not contained) | I2: =VLOOKUP(H2,'Flow Location'!$A$1:$B$21,2,FALSE) -> Storm Sewer (not contained) | J2: 157 | K2: Manhole | L2: =VLOOKUP(K2,'Structure type'!$A$1:$B$15,2,FALSE) -> Manhole | M2: Grease Blockage | N2: =VLOOKUP(M2,'Excursion Cause'!$A$1:$B$34,2,FALSE) -> Grease Blockage | O2: 44287 | P2: 8:35 | Q2: 44287 | R2: 11:11 | S2: 1 | T2: Cleared Main Line;Cleaned and Disinfected | U2: 20210401 | V2: 20210401 | W2: 29.810848 | X2: -95.499751
A3: 10428 | B3: 2021 | C3: =CONCATENATE(D3,",",E3,",",F3) -> 7206 LA PASEO ST,Houston,Texas | D3: 7206 LA PASEO ST | E3: Houston | F3: Texas | G3: 77087 | H3: Storm Sewer (not contained) | I3: =VLOOKUP(H3,'Flow Location'!$A$1:$B$21,2,FALSE) -> Storm Sewer (not contained) | J3: 0 | K3: Manhole | L3: =VLOOKUP(K3,'Structure type'!$A$1:$B$15,2,FALSE) -> Manhole | M3: Grease Blockage | N3: =VLOOKUP(M3,'Excursion Cause'!$A$1:$B$34,2,FALSE) -> Grease Blockage | O3: 44287 | P3: 11:40 | Q3: 44287 | R3: 11:40 | S3: 0 | T3: Cleared Main Line | U3: 20210401 | V3: 20210401 | W3: 29.67863 | X3: -95.300138
A4: 10430 | B4: 2021 | C4: =CONCATENATE(D4,",",E4,",",F4) -> 3502 DARLINGHURST DR,Houston,Texas | D4: 3502 DARLINGHURST DR | E4: Houston | F4: Texas | G4: 77045 | H4: Storm Sewer (not contained) | I4: =VLOOKUP(H4,'Flow Location'!$A$1:$B$21,2,FALSE) -> Storm Sewer (not contained) | J4: 166 | K4: Manhole | L4: =VLOOKUP(K4,'Structure type'!$A$1:$B$15,2,FALSE) -> Manhole | M4: Grease Blockage | N4: =VLOOKUP(M4,'Excursion Cause'!$A$1:$B$34,2,FALSE) -> Grease Blockage | O4: 44287 | P4: 12:25 | Q4: 44287 | R4: 13:47 | S4: 2 | T4: Cleared Main Line;Cleaned and Disinfected | U4: 20210401 | V4: 20210401 | W4: 29.624011 | X4: -95.428274
A5: 10434 | B5: 2021 | C5: =CONCATENATE(D5,",",E5,",",F5) -> 5411 PARDEE ST,Houston,Texas | D5: 5411 PARDEE ST | E5: Houston | F5: Texas | G5: 77026 | H5: Bayou/surface water/drainage ditch | I5: =VLOOKUP(H5,'Flow Location'!$A$1:$B$21,2,FALSE) -> Bayou/surface water/drainage ditch | J5: 0 | K5: City Cleanout | L5: =VLOOKUP(K5,'Structure type'!$A$1:$B$15,2,FALSE) -> City Cleanout | M5: Grease Blockage | N5: =VLOOKUP(M5,'Excursion Cause'!$A$1:$B$34,2,FALSE) -> Grease Blockage | O5: 44287 | P5: 13:44 | Q5: 44287 | R5: 13:44 | S5: 0 | T5: Cleared Main Line;Cleaned and Disinfected;Cleared Service Lateral | U5: 20210401 | V5: 20210401 | W5: 29.805975 | X5: -95.316642
A6: 10436 | B6: 2021 | C6: =CONCATENATE(D6,",",E6,",",F6) -> 12017 PALMCREST ST,Houston,Texas | D6: 12017 PALMCREST ST | E6: Houston | F6: Texas | G6: 77034 | H6: Contained On Site, not within 5 ft. of Bayou/Surface Water/Drainage Ditch | I6: =VLOOKUP(H6,'Flow Location'!$A$1:$B$21,2,FALSE) -> Contained On Site, not within 5 ft. of Bayou/Surface Water/Drainage Ditch | J6: 0 | K6: Private Cleanout | L6: =VLOOKUP(K6,'Structure type'!$A$1:$B$15,2,FALSE) -> Private Cleanout | M6: Collection system structural blockage | N6: =VLOOKUP(M6,'Excursion Cause'!$A$1:$B$34,2,FALSE) -> Collection system structural blockage | O6: 44287 | P6: 14:55 | Q6: 44287 | R6: 14:55 | S6: 0 | T6: Set Bypass Pump;Cleaned and Disinfected | U6: 20210401 | V6: 20210401 | W6: 29.627992 | X6: -95.210625
A7: 10440 | B7: 2021 | C7: =CONCATENATE(D7,",",E7,",",F7) -> 7523 KINGSLEY ST,Houston,Texas | D7: 7523 KINGSLEY ST | E7: Houston | F7: Texas | G7: 77087 | H7: Storm Sewer (not contained) | I7: =VLOOKUP(H7,'Flow Location'!$A$1:$B$21,2,FALSE) -> Storm Sewer (not contained) | J7: 1020 | K7: Manhole | L7: =VLOOKUP(K7,'Structure type'!$A$1:$B$15,2,FALSE) -> Manhole | M7: Rags/Wipes | N7: =VLOOKUP(M7,'Excursion Cause'!$A$1:$B$34,2,FALSE) -> Rags/Wipes | O7: 44288 | P7: 7:54 | Q7: 44288 | R7: 16:24 | S7: 2 | T7: Cleaned and Disinfected;Cleared Main Line | U7: 20210402 | V7: 20210402 | W7: 29.68708 | X7: -95.291863
A8: 10441 | B8: 2021 | C8: =CONCATENATE(D8,",",E8,",",F8) -> 13655 ELLA BLVD,Houston,Texas | D8: 13655 ELLA BLVD | E8: Houston | F8: Texas | G8: 77014 | H8: Storm Sewer (not contained) | I8: =VLOOKUP(H8,'Flow Location'!$A$1:$B$21,2,FALSE) -> Storm Sewer (not contained) | J8: 124 | K8: Manhole | L8: =VLOOKUP(K8,'Structure type'!$A$1:$B$15,2,FALSE) -> Manhole | M8: Grease Blockage | N8: =VLOOKUP(M8,'Excursion Cause'!$A$1:$B$34,2,FALSE) -> Grease Blockage | O8: 44288 | P8: 9:18 | Q8: 44288 | R8: 11:22 | S8: 1 | T8: Cleared Main Line;Cleaned and Disinfected | U8: 20210402 | V8: 20210402 | W8: 29.966839 | X8: -95.430395
A9: 10447 | B9: 2021 | C9: =CONCATENATE(D9,",",E9,",",F9) -> 9605 STELLA LINK RD,Houston,Texas | D9: 9605 STELLA LINK RD | E9: Houston | F9: Texas | G9: 77025 | H9: Storm Sewer (not contained) | I9: =VLOOKUP(H9,'Flow Location'!$A$1:$B$21,2,FALSE) -> Storm Sewer (not contained) | J9: 1036 | K9: Private Cleanout | L9: =VLOOKUP(K9,'Structure type'!$A$1:$B$15,2,FALSE) -> Private Cleanout | M9: Rags/Wipes | N9: =VLOOKUP(M9,'Excursion Cause'!$A$1:$B$34,2,FALSE) -> Rags/Wipes | O9: 44289 | P9: 9:30 | Q9: 44289 | R9: 18:07 | S9: 2 | T9: Cleared Main Line;Cleaned and Disinfected | U9: 20210403 | V9: 20210403 | W9: 29.678771 | X9: -95.439832
A10: 10451 | B10: 2021 | C10: =CONCATENATE(D10,",",E10,",",F10) -> 8950 CHIMNEY ROCK RD,Houston,Texas | D10: 8950 CHIMNEY ROCK RD | E10: Houston | F10: Texas | G10: 77096 | H10: Storm Sewer (not contained) | I10: =VLOOKUP(H10,'Flow Location'!$A$1:$B$21,2,FALSE) -> Storm Sewer (not contained) | J10: 765 | K10: Manhole | L10: =VLOOKUP(K10,'Structure type'!$A$1:$B$15,2,FALSE) -> Manhole | M10: Grease Blockage | N10: =VLOOKUP(M10,'Excursion Cause'!$A$1:$B$34,2,FALSE) -> Grease Blockage | O10: 44289 | P10: 13:05 | Q10: 44289 | R10: 17:20 | S10: 3 | T10: Cleared Main Line;Cleaned and Disinfected | U10: 20210403 | V10: 20210403 | W10: 29.680963 | X10: -95.477007
A11: 10456 | B11: 2021 | C11: =CONCATENATE(D11,",",E11,",",F11) -> 2074 ANTOINE DR,Houston,Texas | D11: 2074 ANTOINE DR | E11: Houston | F11: Texas | G11: 77055 | H11: Contained On Site, not within 5 ft. of Bayou/Surface Water/Drainage Ditch | I11: =VLOOKUP(H11,'Flow Location'!$A$1:$B$21,2,FALSE) -> Contained On Site, not within 5 ft. of Bayou/Surface Water/Drainage Ditch | J11: 0 | K11: City Cleanout | L11: =VLOOKUP(K11,'Structure type'!$A$1:$B$15,2,FALSE) -> City Cleanout | M11: Rags/Wipes | N11: =VLOOKUP(M11,'Excursion Cause'!$A$1:$B$34,2,FALSE) -> Rags/Wipes | O11: 44289 | P11: 18:19 | Q11: 44289 | R11: 18:19 | S11: 0 | T11: Cleaned and Disinfected;Cleared City Clean Out | U11: 20210403 | V11: 20210403 | W11: 29.809231 | X11: -95.475104
A12: 10459 | B12: 2021 | C12: =CONCATENATE(D12,",",E12,",",F12) -> 4000 34TH ST,Houston,Texas | D12: 4000 34TH ST | E12: Houston | F12: Texas | G12: 77092 | H12: Storm Sewer (not contained) | I12: =VLOOKUP(H12,'Flow Location'!$A$1:$B$21,2,FALSE) -> Storm Sewer (not contained) | J12: 445 | K12: Manhole | L12: =VLOOKUP(K12,'Structure type'!$A$1:$B$15,2,FALSE) -> Manhole | M12: Grease Blockage | N12: =VLOOKUP(M12,'Excursion Cause'!$A$1:$B$34,2,FALSE) -> Grease Blockage | O12: 44290 | P12: 13:37 | Q12: 44290 | R12: 15:06 | S12: 5 | T12: Cleaned and Disinfected;Cleared Main Line | U12: 20210404 | V12: 20210404 | W12: 29.817317 | X12: -95.449854
A13: 10461 | B13: 2021 | C13: =CONCATENATE(D13,",",E13,",",F13) -> 1916 BALDWIN ST,Houston,Texas | D13: 1916 BALDWIN ST | E13: Houston | F13: Texas | G13: 77019 | H13: Storm Sewer (not contained) | I13: =VLOOKUP(H13,'Flow Location'!$A$1:$B$21,2,FALSE) -> Storm Sewer (not contained) | J13: 456 | K13: City Cleanout | L13: =VLOOKUP(K13,'Structure type'!$A$1:$B$15,2,FALSE) -> City Cleanout | M13: Collection system structural failure | N13: =VLOOKUP(M13,'Excursion Cause'!$A$1:$B$34,2,FALSE) -> Collection system structural failure | O13: 44290 | P13: 14:47 | Q13: 44290 | R13: 18:35 | S13: 2 | T13: Cleaned and Disinfected;Cleared City Clean Out;Set Bypass Pump | U13: 20210404 | V13: 20210404 | W13: 29.753243 | X13: -95.376752
... A759: 12662 | B759: 2021 | C759: =CONCATENATE(D759,",",E759,",",F759) -> 607 DORCHESTER ST,Houston,Texas | D759: 607 DORCHESTER ST | E759: Houston | F759: Texas | G759: 77022 | H759: Contained On Site, not within 5 ft. of Bayou/Surface Water/Drainage Ditch | I759: =VLOOKUP(H759,'Flow Location'!$A$1:$B$21,2,FALSE) -> Contained On Site, not within 5 ft. of Bayou/Surface Water/Drainage Ditch | J759: 0 | K759: Service Lateral | L759: =VLOOKUP(K759,'Structure type'!$A$1:$B$15,2,FALSE) -> Service Lateral | M759: Collection system structural failure | N759: =VLOOKUP(M759,'Excursion Cause'!$A$1:$B$34,2,FALSE) -> Collection system structural failure | O759: 44530 | P759: 15:32 | Q759: 44530 | R759: 15:32 | S759: 0 | T759: Cleaned and Disinfected | U759: 20211130 | V759: 20211130 | W759: 29.822992 | X759: -95.365131
A760: 12663 | B760: 2021 | C760: =CONCATENATE(D760,",",$E$1863,",",$F$1863) -> 12610 SKYVIEW MANOR DR,Houston,TX | D760: 12610 SKYVIEW MANOR DR | E760: Houston | F760: TX | G760: 77047 | H760: Storm Sewer (not contained) | I760: =VLOOKUP(H760,'Flow Location'!$A$1:$B$21,2,FALSE) -> Storm Sewer (not contained) | J760: 1552 | K760: Manhole | L760: =VLOOKUP(K760,'Structure type'!$A$1:$B$15,2,FALSE) -> Manhole | M760: Grease Blockage | N760: =VLOOKUP(M760,'Excursion Cause'!$A$1:$B$34,2,FALSE) -> Grease Blockage | O760: 44531 | P760: 0.36597222 | Q760: 44531 | R760: 0.90486111 | S760: 2 | T760: Cleared Main Line;Cleaned and Disinfected | W760: 29.622834 | X760: -95.382933
A761: 12666 | B761: 2021 | C761: =CONCATENATE(D761,",",$E$1863,",",$F$1863) -> 10434 BROADSTAIRS ST,Houston,TX | D761: 10434 BROADSTAIRS ST | E761: Houston | F761: TX | G761: 77013 | H761: Storm Sewer (not contained) | I761: =VLOOKUP(H761,'Flow Location'!$A$1:$B$21,2,FALSE) -> Storm Sewer (not contained) | J761: 1417 | K761: Manhole | L761: =VLOOKUP(K761,'Structure type'!$A$1:$B$15,2,FALSE) -> Manhole | M761: Grease Blockage | N761: =VLOOKUP(M761,'Excursion Cause'!$A$1:$B$34,2,FALSE) -> Grease Blockage | O761: 44531 | P761: 0.49513889 | Q761: 44532 | R761: 0.47916667 | S761: 1 | T761: Cleaned and Disinfected;Cleared Main Line | W761: 29.780462 | X761: -95.243019
A762: 12667 | B762: 2021 | C762: =CONCATENATE(D762,",",$E$1863,",",$F$1863) -> 11701 S WILCREST DR,Houston,TX | D762: 11701 S WILCREST DR | E762: Houston | F762: TX | G762: 77099 | H762: Storm Sewer (not contained) | I762: =VLOOKUP(H762,'Flow Location'!$A$1:$B$21,2,FALSE) -> Storm Sewer (not contained) | J762: 885 | K762: Manhole | L762: =VLOOKUP(K762,'Structure type'!$A$1:$B$15,2,FALSE) -> Manhole | M762: Grease Blockage | N762: =VLOOKUP(M762,'Excursion Cause'!$A$1:$B$34,2,FALSE) -> Grease Blockage | O762: 44531 | P762: 0.60625 | Q762: 44531 | R762: 0.81111111 | S762: 3 | T762: Cleaned and Disinfected;Cleared Main Line | W762: 29.655562 | X762: -95.570651
A763: 12669 | B763: 2021 | C763: =CONCATENATE(D763,",",$E$1863,",",$F$1863) -> 2612 MILLS ST,Houston,TX | D763: 2612 MILLS ST | E763: Houston | F763: TX | G763: 77026 | H763: Contained On Site, not within 5 ft. of Bayou/Surface Water/Drainage Ditch | I763: =VLOOKUP(H763,'Flow Location'!$A$1:$B$21,2,FALSE) -> Contained On Site, not within 5 ft. of Bayou/Surface Water/Drainage Ditch | J763: 0 | K763: City Cleanout | L763: =VLOOKUP(K763,'Structure type'!$A$1:$B$15,2,FALSE) -> City Cleanout | M763: Collection system structural blockage | N763: =VLOOKUP(M763,'Excursion Cause'!$A$1:$B$34,2,FALSE) -> Collection system structural blockage | O763: 44531 | P763: 0.67569444 | Q763: 44531 | R763: 0.67569444 | S763: 0 | T763: Cleaned and Disinfected; Set Bypass Pump | W763: 29.777394 | X763: -95.34333
A764: 12671 | B764: 2021 | C764: =CONCATENATE(D764,",",$E$1863,",",$F$1863) -> 910 REDWOOD ST,Houston,TX | D764: 910 REDWOOD ST | E764: Houston | F764: TX | G764: 77023 | H764: Storm Sewer (not contained) | I764: =VLOOKUP(H764,'Flow Location'!$A$1:$B$21,2,FALSE) -> Storm Sewer (not contained) | J764: 900 | K764: Manhole | L764: =VLOOKUP(K764,'Structure type'!$A$1:$B$15,2,FALSE) -> Manhole | M764: Grease Blockage | N764: =VLOOKUP(M764,'Excursion Cause'!$A$1:$B$34,2,FALSE) -> Grease Blockage | O764: 44532 | P764: 0.37152778 | Q764: 44532 | R764: 0.57986111 | S764: 3 | T764: Cleared Main Line;Cleaned and Disinfected | W764: 29.715826 | X764: -95.296529
A765: 12677 | B765: 2021 | C765: =CONCATENATE(D765,",",E765,",",F765) -> 11722 MOSSCREST DR,Houston,Texas | D765: 11722 MOSSCREST DR | E765: Houston | F765: Texas | G765: 77048 | H765: Contained On Site, not within 5 ft. of Bayou/Surface Water/Drainage Ditch | I765: =VLOOKUP(H765,'Flow Location'!$A$1:$B$21,2,FALSE) -> Contained On Site, not within 5 ft. of Bayou/Surface Water/Drainage Ditch | J765: 2296 | K765: Manhole | L765: =VLOOKUP(K765,'Structure type'!$A$1:$B$15,2,FALSE) -> Manhole | M765: Grease Blockage | N765: =VLOOKUP(M765,'Excursion Cause'!$A$1:$B$34,2,FALSE) -> Grease Blockage | O765: 44529 | P765: 15:07 | Q765: 44530 | R765: 10:15 | S765: 2 | T765: Cleared Main Line;Cleaned and Disinfected | U765: 20211129 | V765: 20211130 | W765: 29.633267 | X765: -95.351319
A766: 12679 | B766: 2021 | C766: =CONCATENATE(D766,",",$E$1863,",",$F$1863) -> 1343 TARBERRY RD,Houston,TX | D766: 1343 TARBERRY RD | E766: Houston | F766: TX | G766: 77088 | H766: Contained On Site, not within 5 ft. of Bayou/Surface Water/Drainage Ditch | I766: =VLOOKUP(H766,'Flow Location'!$A$1:$B$21,2,FALSE) -> Contained On Site, not within 5 ft. of Bayou/Surface Water/Drainage Ditch | J766: 1461 | K766: Manhole | L766: =VLOOKUP(K766,'Structure type'!$A$1:$B$15,2,FALSE) -> Manhole | M766: Grease Blockage | N766: =VLOOKUP(M766,'Excursion Cause'!$A$1:$B$34,2,FALSE) -> Grease Blockage | O766: 44532 | P766: 0.475 | Q766: 44533 | R766: 0.45833333 | S766: 1 | T766: Cleaned and Disinfected;Cleared Main Line | W766: 29.883207 | X766: -95.420993
A767: 12680 | B767: 2021 | C767: =CONCATENATE(D767,",",$E$1863,",",$F$1863) -> 6919 LIVERPOOL ST,Houston,TX | D767: 6919 LIVERPOOL ST | E767: Houston | F767: TX | G767: 77021 | H767: Contained On Site, not within 5 ft. of Bayou/Surface Water/Drainage Ditch | I767: =VLOOKUP(H767,'Flow Location'!$A$1:$B$21,2,FALSE) -> Contained On Site, not within 5 ft. of Bayou/Surface Water/Drainage Ditch | J767: 0 | K767: City Cleanout | L767: =VLOOKUP(K767,'Structure type'!$A$1:$B$15,2,FALSE) -> City Cleanout | M767: Collection system structural blockage | N767: =VLOOKUP(M767,'Excursion Cause'!$A$1:$B$34,2,FALSE) -> Collection system structural blockage | O767: 44532 | P767: 0.50347222 | Q767: 44532 | R767: 0.50347222 | S767: 0 | T767: Cleared City Clean Out;Cleaned and Disinfected | W767: 29.686259 | X767: -95.350371
A768: 12685 | B768: 2021 | C768: =CONCATENATE(D768,",",$E$1863,",",$F$1863) -> 3818 BROADWAY ST,Houston,TX | D768: 3818 BROADWAY ST | E768: Houston | F768: TX | G768: 77017 | H768: Storm Sewer (not contained) | I768: =VLOOKUP(H768,'Flow Location'!$A$1:$B$21,2,FALSE) -> Storm Sewer (not contained) | J768: 212 | K768: Manhole | L768: =VLOOKUP(K768,'Structure type'!$A$1:$B$15,2,FALSE) -> Manhole | M768: Grease Blockage | N768: =VLOOKUP(M768,'Excursion Cause'!$A$1:$B$34,2,FALSE) -> Grease Blockage | O768: 44532 | P768: 0.67430556 | Q768: 44532 | R768: 0.74791667 | S768: 2 | T768: Cleared Main Line;Cleaned and Disinfected | W768: 29.686674 | X768: -95.277892
A769: 12686 | B769: 2021 | C769: =CONCATENATE(D769,",",$E$1863,",",$F$1863) -> 7442 DALLAS ST,Houston,TX | D769: 7442 DALLAS ST | E769: Houston | F769: TX | G769: 77011 | H769: Contained On Site, not within 5 ft. of Bayou/Surface Water/Drainage Ditch | I769: =VLOOKUP(H769,'Flow Location'!$A$1:$B$21,2,FALSE) -> Contained On Site, not within 5 ft. of Bayou/Surface Water/Drainage Ditch | J769: 0 | K769: Manhole | L769: =VLOOKUP(K769,'Structure type'!$A$1:$B$15,2,FALSE) -> Manhole | M769: Grease Blockage | N769: =VLOOKUP(M769,'Excursion Cause'!$A$1:$B$34,2,FALSE) -> Grease Blockage | O769: 44532 | P769: 0.68472222 | Q769: 44532 | R769: 0.68472222 | S769: 0 | T769: Cleared Main Line;Cleaned and Disinfected | W769: 29.728525 | X769: -95.295179
A770: 12687 | B770: 2021 | C770: =CONCATENATE(D770,",",$E$1863,",",$F$1863) -> 6001 REIMS RD,Houston,TX | D770: 6001 REIMS RD | E770: Houston | F770: TX | G770: 77036 | H770: Contained On Site, not within 5 ft. of Bayou/Surface Water/Drainage Ditch | I770: =VLOOKUP(H770,'Flow Location'!$A$1:$B$21,2,FALSE) -> Contained On Site, not within 5 ft. of Bayou/Surface Water/Drainage Ditch | J770: 1058 | K770: Manhole | L770: =VLOOKUP(K770,'Structure type'!$A$1:$B$15,2,FALSE) -> Manhole | M770: Rags/Wipes | N770: =VLOOKUP(M770,'Excursion Cause'!$A$1:$B$34,2,FALSE) -> Rags/Wipes | O770: 44533 | P770: 0.33958333 | Q770: 44533 | R770: 0.37361111 | S770: 22 | T770: Cleared Main Line;Cleaned and Disinfected | W770: 29.715436 | X770: -95.515205
A771: 12688 | B771: 2021 | C771: =CONCATENATE(D771,",",$E$1863,",",$F$1863) -> 1317 APACHE ST,Houston,TX | D771: 1317 APACHE ST | E771: Houston | F771: TX | G771: 77022 | H771: Bayou/surface water/drainage ditch | I771: =VLOOKUP(H771,'Flow Location'!$A$1:$B$21,2,FALSE) -> Bayou/surface water/drainage ditch | J771: 0 | K771: Manhole | L771: =VLOOKUP(K771,'Structure type'!$A$1:$B$15,2,FALSE) -> Manhole | M771: Grease Blockage | N771: =VLOOKUP(M771,'Excursion Cause'!$A$1:$B$34,2,FALSE) -> Grease Blockage | O771: 44533 | P771: 0.38055556 | Q771: 44533 | R771: 0.38055556 | S771: 0 | T771: Cleared Main Line;Cleaned and Disinfected | W771: 29.833883 | X771: -95.356573
A772: 12690 | B772: 2021 | C772: =CONCATENATE(D772,",",$E$1863,",",$F$1863) -> 1321 STUDEWOOD ST,Houston,TX | D772: 1321 STUDEWOOD ST | E772: Houston | F772: TX | G772: 77008 | H772: Contained On Site, not within 5 ft. of Bayou/Surface Water/Drainage Ditch | I772: =VLOOKUP(H772,'Flow Location'!$A$1:$B$21,2,FALSE) -> Contained On Site, not within 5 ft. of Bayou/Surface Water/Drainage Ditch | J772: 0 | K772: Private Cleanout | L772: =VLOOKUP(K772,'Structure type'!$A$1:$B$15,2,FALSE) -> Private Cleanout | M772: Collection system structural blockage | N772: =VLOOKUP(M772,'Excursion Cause'!$A$1:$B$34,2,FALSE) -> Collection system structural blockage | O772: 44537 | P772: 0.43541667 | Q772: 44537 | R772: 0.43541667 | S772: 0 | T772: Cleaned and Disinfected;Cleared Service Lateral | W772: 29.79517 | X772: -95.388188
A773: 12698 | B773: 2021 | C773: =CONCATENATE(D773,",",$E$1863,",",$F$1863) -> 1103 APACHE ST,Houston,TX | D773: 1103 APACHE ST | E773: Houston | F773: TX | G773: 77022 | H773: Storm Sewer (not contained) | I773: =VLOOKUP(H773,'Flow Location'!$A$1:$B$21,2,FALSE) -> Storm Sewer (not contained) | J773: 0 | K773: City Cleanout | L773: =VLOOKUP(K773,'Structure type'!$A$1:$B$15,2,FALSE) -> City Cleanout | M773: Grease Blockage | N773: =VLOOKUP(M773,'Excursion Cause'!$A$1:$B$34,2,FALSE) -> Grease Blockage | O773: 44533 | P773: 0.57777778 | Q773: 44533 | R773: 0.57777778 | S773: 0 | T773: Cleared Main Line;Cleaned and Disinfected | W773: 29.833922 | X773: -95.358116
A774: 12699 | B774: 2021 | C774: =CONCATENATE(D774,",",$E$1863,",",$F$1863) -> 910 REDWOOD ST,Houston,TX | D774: 910 REDWOOD ST | E774: Houston | F774: TX | G774: 77023 | H774: Contained On Site, not within 5 ft. of Bayou/Surface Water/Drainage Ditch | I774: =VLOOKUP(H774,'Flow Location'!$A$1:$B$21,2,FALSE) -> Contained On Site, not within 5 ft. of Bayou/Surface Water/Drainage Ditch | J774: 0 | K774: Manhole | L774: =VLOOKUP(K774,'Structure type'!$A$1:$B$15,2,FALSE) -> Manhole | M774: Grease Blockage | N774: =VLOOKUP(M774,'Excursion Cause'!$A$1:$B$34,2,FALSE) -> Grease Blockage | O774: 44533 | P774: 0.58680556 | Q774: 44533 | R774: 0.58680556 | S774: 0 | T774: Cleared Main Line;Cleaned and Disinfected | W774: 29.715826 | X774: -95.296529
A775: 12705 | B775: 2021 | C775: =CONCATENATE(D775,",",$E$1863,",",$F$1863) -> 6707 INDIAN FALLS DR,Houston,TX | D775: 6707 INDIAN FALLS DR | E775: Houston | F775: TX | G775: 77489 | H775: Contained On Site, not within 5 ft. of Bayou/Surface Water/Drainage Ditch | I775: =VLOOKUP(H775,'Flow Location'!$A$1:$B$21,2,FALSE) -> Contained On Site, not within 5 ft. of Bayou/Surface Water/Drainage Ditch | J775: 0 | K775: Private Cleanout | L775: =VLOOKUP(K775,'Structure type'!$A$1:$B$15,2,FALSE) -> Private Cleanout | M775: Grease Blockage | N775: =VLOOKUP(M775,'Excursion Cause'!$A$1:$B$34,2,FALSE) -> Grease Blockage | O775: 44534 | P775: 0.60763889 | Q775: 44534 | R775: 0.60763889 | S775: 0 | T775: Cleared Main Line;Cleaned and Disinfected | W775: 29.599663 | X775: -95.487212
A776: 12706 | B776: 2021 | C776: =CONCATENATE(D776,",",$E$1863,",",$F$1863) -> 7840 CANAL ST,Houston,TX | D776: 7840 CANAL ST | E776: Houston | F776: TX | G776: 77012 | H776: Contained On Site, not within 5 ft. of Bayou/Surface Water/Drainage Ditch | I776: =VLOOKUP(H776,'Flow Location'!$A$1:$B$21,2,FALSE) -> Contained On Site, not within 5 ft. of Bayou/Surface Water/Drainage Ditch | J776: 0 | K776: Service Lateral | L776: =VLOOKUP(K776,'Structure type'!$A$1:$B$15,2,FALSE) -> Service Lateral | M776: Collection system structural failure | N776: =VLOOKUP(M776,'Excursion Cause'!$A$1:$B$34,2,FALSE) -> Collection system structural failure | O776: 44534 | P776: 0.71736111 | Q776: 44534 | R776: 0.71736111 | S776: 0 | T776: Cleared Service Lateral;Cleaned and Disinfected | W776: 29.73383 | X776: -95.282923
A777: 12713 | B777: 2021 | C777: =CONCATENATE(D777,",",$E$1863,",",$F$1863) -> 4807 FALVEY ST,Houston,TX | D777: 4807 FALVEY ST | E777: Houston | F777: TX | G777: 77017 | H777: Contained On Site, not within 5 ft. of Bayou/Surface Water/Drainage Ditch | I777: =VLOOKUP(H777,'Flow Location'!$A$1:$B$21,2,FALSE) -> Contained On Site, not within 5 ft. of Bayou/Surface Water/Drainage Ditch | J777: 0 | K777: City Cleanout | L777: =VLOOKUP(K777,'Structure type'!$A$1:$B$15,2,FALSE) -> City Cleanout | M777: Grease Blockage | N777: =VLOOKUP(M777,'Excursion Cause'!$A$1:$B$34,2,FALSE) -> Grease Blockage | O777: 44536 | P777: 0.35486111 | Q777: 44536 | R777: 0.35486111 | S777: 0 | T777: Cleaned and Disinfected;Cleared Main Line | W777: 29.70007 | X777: -95.24148
... A816: 12831 | B816: 2021 | C816: =CONCATENATE(D816,",",$E$1863,",",$F$1863) -> 425 BYRNE ST,Houston,TX | D816: 425 BYRNE ST | E816: Houston | F816: TX | G816: 77009 | H816: Contained On Site, not within 5 ft. of Bayou/Surface Water/Drainage Ditch | I816: =VLOOKUP(H816,'Flow Location'!$A$1:$B$21,2,FALSE) -> Contained On Site, not within 5 ft. of Bayou/Surface Water/Drainage Ditch | J816: 0 | K816: City Cleanout | L816: =VLOOKUP(K816,'Structure type'!$A$1:$B$15,2,FALSE) -> City Cleanout | M816: Collection system temporary blockage | N816: =VLOOKUP(M816,'Excursion Cause'!$A$1:$B$34,2,FALSE) -> Collection system temporary blockage | O816: 44546 | P816: 0.47847222 | Q816: 44546 | R816: 0.47847222 | S816: 0 | T816: Cleared Service Lateral;Cleaned and Disinfected | W816: 29.784842 | X816: -95.376078
A817: 12832 | B817: 2021 | C817: =CONCATENATE(D817,",",$E$1863,",",$F$1863) -> 6600 HARBOR TOWN DR,Houston,TX | D817: 6600 HARBOR TOWN DR | E817: Houston | F817: TX | G817: 77036 | H817: Storm Sewer ‐ contained | I817: Storm Sewer - contained | J817: 392 | K817: Manhole | L817: =VLOOKUP(K817,'Structure type'!$A$1:$B$15,2,FALSE) -> Manhole | M817: Grease Blockage | N817: =VLOOKUP(M817,'Excursion Cause'!$A$1:$B$34,2,FALSE) -> Grease Blockage | O817: 44546 | P817: 0.53541667 | Q817: 44546 | R817: 0.67083333 | S817: 2 | T817: Cleared Main Line;Cleaned and Disinfected | W817: 29.706584 | X817: -95.530272
A818: 12835 | B818: 2021 | C818: =CONCATENATE(D818,",",$E$1863,",",$F$1863) -> 7322 YOE ST,Houston,TX | D818: 7322 YOE ST | E818: Houston | F818: TX | G818: 77016 | H818: Contained On Site, not within 5 ft. of Bayou/Surface Water/Drainage Ditch | I818: =VLOOKUP(H818,'Flow Location'!$A$1:$B$21,2,FALSE) -> Contained On Site, not within 5 ft. of Bayou/Surface Water/Drainage Ditch | J818: 0 | K818: City Cleanout | L818: =VLOOKUP(K818,'Structure type'!$A$1:$B$15,2,FALSE) -> City Cleanout | M818: Rags/Wipes | N818: =VLOOKUP(M818,'Excursion Cause'!$A$1:$B$34,2,FALSE) -> Rags/Wipes | O818: 44546 | P818: 0.6625 | Q818: 44546 | R818: 0.6625 | S818: 0 | T818: Cleared City Clean Out; Cleaned and Disinfected | W818: 29.858196 | X818: -95.29497
A819: 12836 | B819: 2021 | C819: =CONCATENATE(D819,",",$E$1863,",",$F$1863) -> 7215 HILLSBORO ST,Houston,TX | D819: 7215 HILLSBORO ST | E819: Houston | F819: TX | G819: 77020 | H819: Contained On Site, not within 5 ft. of Bayou/Surface Water/Drainage Ditch | I819: =VLOOKUP(H819,'Flow Location'!$A$1:$B$21,2,FALSE) -> Contained On Site, not within 5 ft. of Bayou/Surface Water/Drainage Ditch | J819: 0 | K819: Private Cleanout | L819: =VLOOKUP(K819,'Structure type'!$A$1:$B$15,2,FALSE) -> Private Cleanout | M819: Grease Blockage | N819: =VLOOKUP(M819,'Excursion Cause'!$A$1:$B$34,2,FALSE) -> Grease Blockage | O819: 44546 | P819: 0.71666667 | Q819: 44546 | R819: 0.71666667 | S819: 0 | T819: Cleared Private Line;Cleaned and Disinfected | W819: 29.780234 | X819: -95.297285
A820: 12844 | B820: 2021 | C820: =CONCATENATE(D820,",",$E$1863,",",$F$1863) -> 900 BROADWAY ST,Houston,TX | D820: 900 BROADWAY ST | E820: Houston | F820: TX | G820: 77012 | H820: Bayou/surface water/drainage ditch | I820: =VLOOKUP(H820,'Flow Location'!$A$1:$B$21,2,FALSE) -> Bayou/surface water/drainage ditch | J820: 0 | K820: Service Lateral | L820: =VLOOKUP(K820,'Structure type'!$A$1:$B$15,2,FALSE) -> Service Lateral | M820: Grease Blockage | N820: =VLOOKUP(M820,'Excursion Cause'!$A$1:$B$34,2,FALSE) -> Grease Blockage | O820: 44547 | P820: 0.44097222 | Q820: 44547 | R820: 0.44097222 | S820: 0 | T820: Cleaned and Disinfected;Cleared Private Line | W820: 29.717705 | X820: -95.278811
A821: 12848 | B821: 2021 | C821: =CONCATENATE(D821,",",$E$1863,",",$F$1863) -> 1350 LATHROP ST,Houston,TX | D821: 1350 LATHROP ST | E821: Houston | F821: TX | G821: 77020 | H821: Contained On Site, not within 5 ft. of Bayou/Surface Water/Drainage Ditch | I821: =VLOOKUP(H821,'Flow Location'!$A$1:$B$21,2,FALSE) -> Contained On Site, not within 5 ft. of Bayou/Surface Water/Drainage Ditch | J821: 0 | K821: Private Cleanout | L821: =VLOOKUP(K821,'Structure type'!$A$1:$B$15,2,FALSE) -> Private Cleanout | M821: Collection system temporary blockage | N821: =VLOOKUP(M821,'Excursion Cause'!$A$1:$B$34,2,FALSE) -> Collection system temporary blockage | O821: 44547 | P821: 0.52777778 | Q821: 44547 | R821: 0.52777778 | S821: 0 | T821: Cleaned and Disinfected;Cleared Service Lateral | W821: 29.763432 | X821: -95.301927
A822: 12849 | B822: 2021 | C822: =CONCATENATE(D822,",",$E$1863,",",$F$1863) -> 5214 NORTHRIDGE DR,Houston,TX | D822: 5214 NORTHRIDGE DR | E822: Houston | F822: TX | G822: 77033 | H822: Contained On Site, not within 5 ft. of Bayou/Surface Water/Drainage Ditch | I822: =VLOOKUP(H822,'Flow Location'!$A$1:$B$21,2,FALSE) -> Contained On Site, not within 5 ft. of Bayou/Surface Water/Drainage Ditch | J822: 0 | K822: Service Lateral | L822: =VLOOKUP(K822,'Structure type'!$A$1:$B$15,2,FALSE) -> Service Lateral | M822: Collection system structural failure | N822: =VLOOKUP(M822,'Excursion Cause'!$A$1:$B$34,2,FALSE) -> Collection system structural failure | O822: 44547 | P822: 0.52847222 | Q822: 44547 | R822: 0.52847222 | S822: 0 | T822: Cleared Service Lateral;Cleaned and Disinfected | W822: 29.670177 | X822: -95.345017
A823: 12850 | B823: 2021 | C823: =CONCATENATE(D823,",",$E$1863,",",$F$1863) -> 11150 BEECHNUT ST,Houston,TX | D823: 11150 BEECHNUT ST | E823: Houston | F823: TX | G823: 77072 | H823: Contained On Site, not within 5 ft. of Bayou/Surface Water/Drainage Ditch | I823: =VLOOKUP(H823,'Flow Location'!$A$1:$B$21,2,FALSE) -> Contained On Site, not within 5 ft. of Bayou/Surface Water/Drainage Ditch | J823: 1112 | K823: City Cleanout | L823: =VLOOKUP(K823,'Structure type'!$A$1:$B$15,2,FALSE) -> City Cleanout | M823: Grease Blockage | N823: =VLOOKUP(M823,'Excursion Cause'!$A$1:$B$34,2,FALSE) -> Grease Blockage | O823: 44547 | P823: 0.67569444 | Q823: 44548 | R823: 0.44791667 | S823: 1 | T823: Cleaned and Disinfected;Cleared City Clean Out | W823: 29.688364 | X823: -95.57383
...

Sheet Excursion Cause
A1: Excursion_Cause | B1: Corrected
A2: Air Relief Valve (ARV) Failure | B2: Air Relief Valve (ARV) Failure
A3: Air Relief Valve (ARV) Failure | B3: Air Relief Valve (ARV) Failure
A4: Collection system ‐ wet weather | B4: Collection system ‐ wet weather
A5: Collection system - wet weather | B5: Collection system ‐ wet weather
A6: Collection system structural blockage | B6: Collection system structural blockage
A7: Collection system structural failure | B7: Collection system structural failure
A8: Collection system structural blockage | B8: Collection system structural blockage
A9: Collection system structural failure | B9: Collection system structural failure
A10: Collection system temporary blockage | B10: Collection system temporary blockage
A11: Collection system temporary blockage | B11: Collection system temporary blockage
A12: Collection system wet weather | B12: Collection system wet weather
... A34: WWTP Mechanical Failure | B34: WWTP Mechanical Failure

Sheet Structure type
A1: Structure_Type | B1: Corrected
A2: City Cleanout | B2: City Cleanout
A3: Private Cleanout | B3: Private Cleanout
A4: Service Lateral | B4: Service Lateral
A5: Gravity Main | B5: Gravity Main
A6: Manhole | B6: Manhole
A7: Force Main | B7: Force Main
A8: Private Sample Well | B8: Private Sample Well
A9: Private Grease Trap | B9: Private Grease Trap
A10: Private Cleanout | B10: Private Cleanout
A11: Private Sample Well | B11: Private Sample Well
A12: Private Sample Well | B12: Private Sample Well
... A15: Lift Station | B15: Lift Station

Sheet Flow Location
A1: Flow_Location | B1: Corrected
A2: Bayou/surface water/drainage ditch | B2: Bayou/surface water/drainage ditch
A3: Contained On Site, not within 5 ft. of Bayou/Surface Water/Drainage Ditch | B3: Contained On Site, not within 5 ft. of Bayou/Surface Water/Drainage Ditch
A4: Storm Sewer - contained | B4: Storm Sewer - contained
A5: Storm Sewer (not contained) | B5: Storm Sewer (not contained)
A6: Within 5 ft. of Bayou/Surface Water/Drainage Ditch | B6: Within 5 ft. of Bayou/Surface Water/Drainage Ditch
A7: Contained On Site, not within 5 ft. of Bayou/Surface Water/Drainage Ditch | B7: Contained On Site, not within 5 ft. of Bayou/Surface Water/Drainage Ditch
A8: Storm Sewer (not contained) | B8: Storm Sewer (not contained)
A9: Storm Sewer ‐ contained | B9: Storm Sewer - contained
A10: Within 5 ft. of Bayou/Surface Water/Drainage Ditch | B10: Within 5 ft. of Bayou/Surface Water/Drainage Ditch
A11: Bayou/surface water/drainage ditch | B11: Bayou/surface water/drainage ditch
A12: Drainage Ditch | B12: Drainage Ditch
... A21: Contained On Site, not within 5 ft. of Bayou/Surface Water/Drainage Ditch | B21: Contained On Site, not within 5 ft. of Bayou/Surface Water/Drainage Ditch
